<?xml version="1.0" encoding="UTF-8"?>
<testng-results ignored="0" total="4" passed="2" failed="2" skipped="0">
  <reporter-output>
  </reporter-output>
  <suite started-at="2024-09-06T09:32:43 IST" name="parallelSuite" finished-at="2024-09-06T09:33:21 IST" duration-ms="37279">
    <groups>
      <group name="ErrorHandling">
        <method signature="ErrorValidationTest.LoginErrorValidation()[pri:0, instance:testCases.ErrorValidationTest@14028087]" name="LoginErrorValidation" class="testCases.ErrorValidationTest"/>
        <method signature="ErrorValidationTest.ProductErrorValidation()[pri:0, instance:testCases.ErrorValidationTest@14028087]" name="ProductErrorValidation" class="testCases.ErrorValidationTest"/>
      </group> <!-- ErrorHandling -->
    </groups>
    <test started-at="2024-09-06T09:32:43 IST" name="Submit Order Test" finished-at="2024-09-06T09:33:02 IST" duration-ms="18774">
      <class name="testCases.SubmitOrderTest">
        <test-method is-config="true" signature="launchApplication()[pri:0, instance:testCases.SubmitOrderTest@20140db9]" started-at="2024-09-06T09:32:43 IST" name="launchApplication" finished-at="2024-09-06T09:32:49 IST" duration-ms="5698" status="PASS">
          <reporter-output>
          </reporter-output>
        </test-method> <!-- launchApplication -->
        <test-method signature="submitOrder()[pri:0, instance:testCases.SubmitOrderTest@20140db9]" started-at="2024-09-06T09:32:49 IST" name="submitOrder" finished-at="2024-09-06T09:32:55 IST" duration-ms="6235" status="PASS">
          <reporter-output>
          </reporter-output>
        </test-method> <!-- submitOrder -->
        <test-method is-config="true" signature="tearDown()[pri:0, instance:testCases.SubmitOrderTest@20140db9]" started-at="2024-09-06T09:32:55 IST" name="tearDown" finished-at="2024-09-06T09:32:56 IST" duration-ms="308" status="PASS">
          <reporter-output>
          </reporter-output>
        </test-method> <!-- tearDown -->
        <test-method is-config="true" signature="launchApplication()[pri:0, instance:testCases.SubmitOrderTest@20140db9]" started-at="2024-09-06T09:32:56 IST" name="launchApplication" finished-at="2024-09-06T09:33:00 IST" duration-ms="4406" status="PASS">
          <reporter-output>
          </reporter-output>
        </test-method> <!-- launchApplication -->
        <test-method signature="OrderHistory()[pri:0, instance:testCases.SubmitOrderTest@20140db9]" started-at="2024-09-06T09:33:00 IST" name="OrderHistory" finished-at="2024-09-06T09:33:02 IST" depends-on-methods="testCases.SubmitOrderTest.submitOrder" duration-ms="1764" status="PASS">
          <reporter-output>
          </reporter-output>
        </test-method> <!-- OrderHistory -->
        <test-method is-config="true" signature="tearDown()[pri:0, instance:testCases.SubmitOrderTest@20140db9]" started-at="2024-09-06T09:33:02 IST" name="tearDown" finished-at="2024-09-06T09:33:02 IST" duration-ms="276" status="PASS">
          <reporter-output>
          </reporter-output>
        </test-method> <!-- tearDown -->
      </class> <!-- testCases.SubmitOrderTest -->
    </test> <!-- Submit Order Test -->
    <test started-at="2024-09-06T09:32:43 IST" name="Error Validation Test" finished-at="2024-09-06T09:33:21 IST" duration-ms="37279">
      <class name="testCases.ErrorValidationTest">
        <test-method is-config="true" signature="launchApplication()[pri:0, instance:testCases.ErrorValidationTest@14028087]" started-at="2024-09-06T09:32:43 IST" name="launchApplication" finished-at="2024-09-06T09:32:50 IST" duration-ms="6458" status="PASS">
          <reporter-output>
          </reporter-output>
        </test-method> <!-- launchApplication -->
        <test-method signature="LoginErrorValidation()[pri:0, instance:testCases.ErrorValidationTest@14028087]" started-at="2024-09-06T09:32:50 IST" name="LoginErrorValidation" finished-at="2024-09-06T09:32:51 IST" duration-ms="1030" status="FAIL">
          <exception class="java.lang.AssertionError">
            <message>
              <![CDATA[expected [Incorrect email or password.] but found [Incorrect email or password]]]>
            </message>
            <full-stacktrace>
              <![CDATA[java.lang.AssertionError: expected [Incorrect email or password.] but found [Incorrect email or password]
at org.testng.Assert.fail(Assert.java:99)
at org.testng.Assert.failNotEquals(Assert.java:1037)
at org.testng.Assert.assertEqualsImpl(Assert.java:140)
at org.testng.Assert.assertEquals(Assert.java:122)
at org.testng.Assert.assertEquals(Assert.java:629)
at org.testng.Assert.assertEquals(Assert.java:639)
at testCases.ErrorValidationTest.LoginErrorValidation(ErrorValidationTest.java:19)
at java.base/jdk.internal.reflect.DirectMethodHandleAccessor.invoke(DirectMethodHandleAccessor.java:103)
at java.base/java.lang.reflect.Method.invoke(Method.java:580)
at org.testng.internal.MethodInvocationHelper.invokeMethod(MethodInvocationHelper.java:133)
at org.testng.internal.TestInvoker.invokeMethod(TestInvoker.java:598)
at org.testng.internal.TestInvoker.invokeTestMethod(TestInvoker.java:173)
at org.testng.internal.MethodRunner.runInSequence(MethodRunner.java:46)
at org.testng.internal.TestInvoker$MethodInvocationAgent.invoke(TestInvoker.java:824)
at org.testng.internal.TestInvoker.invokeTestMethods(TestInvoker.java:146)
at org.testng.internal.TestMethodWorker.invokeTestMethods(TestMethodWorker.java:146)
at org.testng.internal.TestMethodWorker.run(TestMethodWorker.java:128)
at java.base/java.util.ArrayList.forEach(ArrayList.java:1597)
at org.testng.TestRunner.privateRun(TestRunner.java:794)
at org.testng.TestRunner.run(TestRunner.java:596)
at org.testng.SuiteRunner.runTest(SuiteRunner.java:377)
at org.testng.SuiteRunner.access$000(SuiteRunner.java:28)
at org.testng.SuiteRunner$SuiteWorker.run(SuiteRunner.java:418)
at org.testng.internal.thread.ThreadUtil.lambda$execute$0(ThreadUtil.java:64)
at java.base/java.util.concurrent.FutureTask.run(FutureTask.java:317)
at java.base/java.util.concurrent.ThreadPoolExecutor.runWorker(ThreadPoolExecutor.java:1144)
at java.base/java.util.concurrent.ThreadPoolExecutor$Worker.run(ThreadPoolExecutor.java:642)
at java.base/java.lang.Thread.run(Thread.java:1570)
]]>
            </full-stacktrace>
          </exception> <!-- java.lang.AssertionError -->
          <reporter-output>
          </reporter-output>
        </test-method> <!-- LoginErrorValidation -->
        <test-method is-config="true" signature="tearDown()[pri:0, instance:testCases.ErrorValidationTest@14028087]" started-at="2024-09-06T09:32:51 IST" name="tearDown" finished-at="2024-09-06T09:32:51 IST" duration-ms="293" status="PASS">
          <reporter-output>
          </reporter-output>
        </test-method> <!-- tearDown -->
        <test-method is-config="true" signature="launchApplication()[pri:0, instance:testCases.ErrorValidationTest@14028087]" started-at="2024-09-06T09:32:51 IST" name="launchApplication" finished-at="2024-09-06T09:32:56 IST" duration-ms="4351" status="PASS">
          <reporter-output>
          </reporter-output>
        </test-method> <!-- launchApplication -->
        <test-method signature="ProductErrorValidation()[pri:0, instance:testCases.ErrorValidationTest@14028087]" started-at="2024-09-06T09:32:56 IST" name="ProductErrorValidation" finished-at="2024-09-06T09:33:20 IST" duration-ms="24664" status="FAIL">
          <exception class="java.lang.AssertionError">
            <message>
              <![CDATA[expected [true] but found [false]]]>
            </message>
            <full-stacktrace>
              <![CDATA[java.lang.AssertionError: expected [true] but found [false]
at org.testng.Assert.fail(Assert.java:99)
at org.testng.Assert.failNotEquals(Assert.java:1037)
at org.testng.Assert.assertTrue(Assert.java:45)
at org.testng.Assert.assertTrue(Assert.java:55)
at testCases.ErrorValidationTest.ProductErrorValidation(ErrorValidationTest.java:29)
at java.base/jdk.internal.reflect.DirectMethodHandleAccessor.invoke(DirectMethodHandleAccessor.java:103)
at java.base/java.lang.reflect.Method.invoke(Method.java:580)
at org.testng.internal.MethodInvocationHelper.invokeMethod(MethodInvocationHelper.java:133)
at org.testng.internal.TestInvoker.invokeMethod(TestInvoker.java:598)
at org.testng.internal.TestInvoker.invokeTestMethod(TestInvoker.java:173)
at org.testng.internal.MethodRunner.runInSequence(MethodRunner.java:46)
at org.testng.internal.TestInvoker$MethodInvocationAgent.invoke(TestInvoker.java:824)
at org.testng.internal.TestInvoker.invokeTestMethods(TestInvoker.java:146)
at org.testng.internal.TestMethodWorker.invokeTestMethods(TestMethodWorker.java:146)
at org.testng.internal.TestMethodWorker.run(TestMethodWorker.java:128)
at java.base/java.util.ArrayList.forEach(ArrayList.java:1597)
at org.testng.TestRunner.privateRun(TestRunner.java:794)
at org.testng.TestRunner.run(TestRunner.java:596)
at org.testng.SuiteRunner.runTest(SuiteRunner.java:377)
at org.testng.SuiteRunner.access$000(SuiteRunner.java:28)
at org.testng.SuiteRunner$SuiteWorker.run(SuiteRunner.java:418)
at org.testng.internal.thread.ThreadUtil.lambda$execute$0(ThreadUtil.java:64)
at java.base/java.util.concurrent.FutureTask.run(FutureTask.java:317)
at java.base/java.util.concurrent.ThreadPoolExecutor.runWorker(ThreadPoolExecutor.java:1144)
at java.base/java.util.concurrent.ThreadPoolExecutor$Worker.run(ThreadPoolExecutor.java:642)
at java.base/java.lang.Thread.run(Thread.java:1570)
]]>
            </full-stacktrace>
          </exception> <!-- java.lang.AssertionError -->
          <reporter-output>
          </reporter-output>
        </test-method> <!-- ProductErrorValidation -->
        <test-method is-config="true" signature="tearDown()[pri:0, instance:testCases.ErrorValidationTest@14028087]" started-at="2024-09-06T09:33:20 IST" name="tearDown" finished-at="2024-09-06T09:33:21 IST" duration-ms="406" status="PASS">
          <reporter-output>
          </reporter-output>
        </test-method> <!-- tearDown -->
      </class> <!-- testCases.ErrorValidationTest -->
    </test> <!-- Error Validation Test -->
  </suite> <!-- parallelSuite -->
</testng-results>
